Traceback (most recent call last):
  File "/Users/icdc/Documents/NFDI/Kemeng/myenv/venvBook/lib/python3.12/site-packages/jupyter_cache/executors/utils.py", line 58, in single_nb_execution
    executenb(
  File "/Users/icdc/Documents/NFDI/Kemeng/myenv/venvBook/lib/python3.12/site-packages/nbclient/client.py", line 1314, in execute
    return NotebookClient(nb=nb, resources=resources, km=km, **kwargs).execute()
           ^^^^^^^^^^^^^^^^^^^^^^^^^^^^^^^^^^^^^^^^^^^^^^^^^^^^^^^^^^^^^^^^^^^^^
  File "/Users/icdc/Documents/NFDI/Kemeng/myenv/venvBook/lib/python3.12/site-packages/jupyter_core/utils/__init__.py", line 165, in wrapped
    return loop.run_until_complete(inner)
           ^^^^^^^^^^^^^^^^^^^^^^^^^^^^^^
  File "/Library/Frameworks/Python.framework/Versions/3.12/lib/python3.12/asyncio/base_events.py", line 664, in run_until_complete
    return future.result()
           ^^^^^^^^^^^^^^^
  File "/Users/icdc/Documents/NFDI/Kemeng/myenv/venvBook/lib/python3.12/site-packages/nbclient/client.py", line 709, in async_execute
    await self.async_execute_cell(
  File "/Users/icdc/Documents/NFDI/Kemeng/myenv/venvBook/lib/python3.12/site-packages/nbclient/client.py", line 1062, in async_execute_cell
    await self._check_raise_for_error(cell, cell_index, exec_reply)
  File "/Users/icdc/Documents/NFDI/Kemeng/myenv/venvBook/lib/python3.12/site-packages/nbclient/client.py", line 918, in _check_raise_for_error
    raise CellExecutionError.from_cell_and_msg(cell, exec_reply_content)
nbclient.exceptions.CellExecutionError: An error occurred while executing the following cell:
------------------
# Observing the Dataset
ds_anacapa1 = xr.open_dataset(ts_files[0], decode_times=True)
ds_anacapa2 = xr.open_dataset(ts_files[2], decode_times=True)
print(ds_anacapa1.ID.data, ds_anacapa2.ID.data)

print(ds_anacapa1.TIME.data[:10])
print(ds_anacapa2.TIME.data[:10])

print(ds_anacapa1.TIME.plot(alpha=0.3))
print(ds_anacapa2.TIME.plot(alpha=0.3))
------------------


[0;31m---------------------------------------------------------------------------[0m
[0;31mAttributeError[0m                            Traceback (most recent call last)
Cell [0;32mIn[11], line 4[0m
[1;32m      2[0m ds_anacapa1 [38;5;241m=[39m xr[38;5;241m.[39mopen_dataset(ts_files[[38;5;241m0[39m], decode_times[38;5;241m=[39m[38;5;28;01mTrue[39;00m)
[1;32m      3[0m ds_anacapa2 [38;5;241m=[39m xr[38;5;241m.[39mopen_dataset(ts_files[[38;5;241m2[39m], decode_times[38;5;241m=[39m[38;5;28;01mTrue[39;00m)
[0;32m----> 4[0m [38;5;28mprint[39m(ds_anacapa1[38;5;241m.[39mID[38;5;241m.[39mdata, [43mds_anacapa2[49m[38;5;241;43m.[39;49m[43mID[49m[38;5;241m.[39mdata)
[1;32m      6[0m [38;5;28mprint[39m(ds_anacapa1[38;5;241m.[39mTIME[38;5;241m.[39mdata[:[38;5;241m10[39m])
[1;32m      7[0m [38;5;28mprint[39m(ds_anacapa2[38;5;241m.[39mTIME[38;5;241m.[39mdata[:[38;5;241m10[39m])

File [0;32m~/Documents/NFDI/Kemeng/myenv/venvNetcdf/lib/python3.12/site-packages/xarray/core/common.py:286[0m, in [0;36mAttrAccessMixin.__getattr__[0;34m(self, name)[0m
[1;32m    284[0m         [38;5;28;01mwith[39;00m suppress([38;5;167;01mKeyError[39;00m):
[1;32m    285[0m             [38;5;28;01mreturn[39;00m source[name]
[0;32m--> 286[0m [38;5;28;01mraise[39;00m [38;5;167;01mAttributeError[39;00m(
[1;32m    287[0m     [38;5;124mf[39m[38;5;124m"[39m[38;5;132;01m{[39;00m[38;5;28mtype[39m([38;5;28mself[39m)[38;5;241m.[39m[38;5;18m__name__[39m[38;5;132;01m!r}[39;00m[38;5;124m object has no attribute [39m[38;5;132;01m{[39;00mname[38;5;132;01m!r}[39;00m[38;5;124m"[39m
[1;32m    288[0m )

[0;31mAttributeError[0m: 'Dataset' object has no attribute 'ID'

